Workbook

Sheet Dashboard
B1: Executive Delivery Dashboard | K1: DELIVERY CON CHARLY BRITO
B2: =Settings!$C$7&" · "&Settings!$C$8&" · Cut-off: "&TEXT(INDEX('Weekly Tracking'!$C$6:$C$29,COUNT('Weekly Tracking'!$E$6:$E$29)),"DD/MM/YYYY")&" · "&Settings!$C$10&" "&COUNT('Weekly Tracking'!$E$6:$E$29)&" of "&COUNT('Weekly Tracking'!$D$6:$D$29)&" · "&Settings!$C$9 -> Demo Project · Platform migration · Demo Client · Cut-off: 02/10/2026 · Week 6 of 12 · [Your name]
B5: ACTUAL PROGRESS | D5: SPI · SCHEDULE | F5: CPI · COST | H5: ACCEPTANCE | J5: OPEN RISKS | L5: OVERALL STATUS
B6: =INDEX('Weekly Tracking'!$E$6:$E$29,COUNT('Weekly Tracking'!$E$6:$E$29)) -> 0.41 | D6: =INDEX('Weekly Tracking'!$I$6:$I$29,COUNT('Weekly Tracking'!$E$6:$E$29)) -> 0.91111111 | F6: =INDEX('Weekly Tracking'!$J$6:$J$29,COUNT('Weekly Tracking'!$E$6:$E$29)) -> 0.984 | H6: =IF(COUNTA(Deliverables!$C$6:$C$35)-COUNTIF(Deliverables!$G$6:$G$35,Settings!$C$36)=0,"",COUNTIF(Deliverables!$G$6:$G$35,Settings!$C$39)/(COUNTA(Deliverables!$C$6:$C$35)-COUNTIF(Deliverables!$G$6:$G$35,Settings!$C$36))) -> 0.6 | J6: =COUNTIF(Risks!$M$6:$M$35,Settings!$C$44) -> 5 | L6: =IF(COUNTIF(B9:K9,"*"&Settings!$C$33&"*")>0,Settings!$C$33,IF(COUNTIF(B9:K9,"*"&Settings!$C$32&"*")>0,Settings!$C$32,Settings!$C$31)) -> Off track
B8: ="Plan "&TEXT(INDEX('Weekly Tracking'!$D$6:$D$29,COUNT('Weekly Tracking'!$E$6:$E$29)),"0%")&" · "&TEXT(INDEX('Weekly Tracking'!$K$6:$K$29,COUNT('Weekly Tracking'!$E$6:$E$29))*100,"+0;-0;0")&" pts" -> Plan 45% · -4 pts | D8: ="EV / PV · 1.00 = on plan" -> EV / PV · 1.00 = on plan | F8: ="EV "&Settings!$C$14&TEXT(INDEX('Weekly Tracking'!$H$6:$H$29,COUNT('Weekly Tracking'!$E$6:$E$29))/Settings!$C$17,IF(Settings!$C$17>=1000000,"#,##0.0","#,##0"))&Settings!$C$18&" · AC "&Settings!$C$14&TEXT(INDEX('Weekly Tracking'!$G$6:$G$29,COUNT('Weekly Tracking'!$E$6:$E$29))/Settings!$C$17,IF(Settings!$C$17>=1000000,"#,##0.0","#,##0"))&Settings!$C$18 -> EV US$984k · AC US$1,000k | H8: =COUNTIF(Deliverables!$G$6:$G$35,Settings!$C$39)&" of "&(COUNTA(Deliverables!$C$6:$C$35)-COUNTIF(Deliverables!$G$6:$G$35,Settings!$C$36))&" delivered · "&COUNTIF(Deliverables!$I$6:$I$35,">"&Settings!$C$25)&" overdue" -> 3 of 5 delivered · 1 overdue | J8: =COUNTIFS(Risks!$M$6:$M$35,Settings!$C$44,Risks!$L$6:$L$35,Settings!$C$46)&" critical · "&COUNTIFS(Risks!$M$6:$M$35,Settings!$C$44,Risks!$N$6:$N$35,"No")&" missing 4 fields" -> 2 critical · 1 missing 4 fields
B9: =IF(-INDEX('Weekly Tracking'!$K$6:$K$29,COUNT('Weekly Tracking'!$E$6:$E$29))>=Settings!$C$22,"● "&Settings!$C$33,IF(-INDEX('Weekly Tracking'!$K$6:$K$29,COUNT('Weekly Tracking'!$E$6:$E$29))>=Settings!$C$21,"● "&Settings!$C$32,"● "&Settings!$C$31)) -> ● On track | D9: =IF(D6<Settings!$C$24,"● "&Settings!$C$33,IF(D6<Settings!$C$23,"● "&Settings!$C$32,"● "&Settings!$C$31)) -> ● At risk | F9: =IF(F6<Settings!$C$24,"● "&Settings!$C$33,IF(F6<Settings!$C$23,"● "&Settings!$C$32,"● "&Settings!$C$31)) -> ● On track | H9: =IF(COUNTIF(Deliverables!$I$6:$I$35,">"&Settings!$C$25)>0,"● "&Settings!$C$33,IF(COUNTIF(Deliverables!$G$6:$G$35,Settings!$C$38)>0,"● "&Settings!$C$32,"● "&Settings!$C$31)) -> ● Off track | J9: =IF(COUNTIFS(Risks!$M$6:$M$35,Settings!$C$44,Risks!$L$6:$L$35,Settings!$C$46)>0,"● "&Settings!$C$33,IF(OR(COUNTIFS(Risks!$M$6:$M$35,Settings!$C$44,Risks!$N$6:$N$35,"No")>0,COUNTIF(Risks!$O$6:$O$35,"Yes")>0,COUNTIFS(Risks!$M$6:$M$35,Settings!$C$44,Risks!$L$6:$L$35,Settings!$C$47)>0),"● "&Settings!$C$32,"● "&Settings!$C$31)) -> ● Off track | L9: =COUNTIF(B9:K9,"*"&Settings!$C$33&"*")&" "&LOWER(Settings!$C$33)&" · "&COUNTIF(B9:K9,"*"&Settings!$C$32&"*")&" "&LOWER(Settings!$C$32) -> 2 off track · 1 at risk
B11: Earned value · this week's reading
B12: PV, EV and AC at cut-off; SPI(t) measures delay in time; verified progress applies the rule chosen in Settings.
B13: PV · PLANNED TO DATE | D13: EV · EARNED VALUE | F13: AC · ACTUAL COST | H13: SPI(t) · TIME | J13: SCHEDULE GAP (PERIODS) | L13: VERIFIED PROGRESS
B14: =Settings!$C$14&TEXT(INDEX('Weekly Tracking'!$F$6:$F$29,COUNT('Weekly Tracking'!$E$6:$E$29))/Settings!$C$17,IF(Settings!$C$17>=1000000,"#,##0.0","#,##0"))&Settings!$C$18 -> US$1,080k | D14: =Settings!$C$14&TEXT(INDEX('Weekly Tracking'!$H$6:$H$29,COUNT('Weekly Tracking'!$E$6:$E$29))/Settings!$C$17,IF(Settings!$C$17>=1000000,"#,##0.0","#,##0"))&Settings!$C$18 -> US$984k | F14: =Settings!$C$14&TEXT(INDEX('Weekly Tracking'!$G$6:$G$29,COUNT('Weekly Tracking'!$E$6:$E$29))/Settings!$C$17,IF(Settings!$C$17>=1000000,"#,##0.0","#,##0"))&Settings!$C$18 -> US$1,000k | H14: =INDEX('Weekly Tracking'!$N$6:$N$29,COUNT('Weekly Tracking'!$E$6:$E$29)) -> 0.93939394 | J14: =INDEX('Weekly Tracking'!$O$6:$O$29,COUNT('Weekly Tracking'!$E$6:$E$29)) -> -0.36363636 | L14: =SUM(Deliverables!$N$6:$N$35) -> 0.4
B15: ="Value that should be done" -> Value that should be done | D15: ="Actual progress "&TEXT(INDEX('Weekly Tracking'!$E$6:$E$29,COUNT('Weekly Tracking'!$E$6:$E$29)),"0%")&" × budget" -> Actual progress 41% × budget | F15: ="Spent to date" -> Spent to date | H15: ="ES / elapsed periods" -> ES / elapsed periods | J15: ="ES "&TEXT(INDEX('Weekly Tracking'!$M$6:$M$29,COUNT('Weekly Tracking'!$E$6:$E$29)),"0.0")&" of "&COUNT('Weekly Tracking'!$E$6:$E$29)&" "&LOWER(Settings!$C$10)&"(s)" -> ES 5.6 of 6 week(s) | L15: ="Rule "&Settings!$C$19&" · SPI "&TEXT(SUM(Deliverables!$N$6:$N$35)*Settings!$C$15/INDEX('Weekly Tracking'!$F$6:$F$29,COUNT('Weekly Tracking'!$E$6:$E$29)),"0.00") -> Rule 50/50 · SPI 0.89
B18: S-curve · cumulative progress | H18: Cumulative cost
B19: Plan vs. actual; the gap between the lines is the delay. | H19: ="Plan (PV) vs. actual cost (AC), in "&Settings!$C$13&" (axis in thousands)." -> Plan (PV) vs. actual cost (AC), in USD (axis in thousands).
B35: Client acceptance | H35: Heat map of open risks
B36: Deliverables by status. Delivered is not accepted. | H36: Number of risks by probability and impact.
H37: Probability ↓ / Impact → | P37: Status | Q37: Deliverables
H38: 5 | I38: =COUNTIFS(Risks!$I$6:$I$35,$H38,Risks!$J$6:$J$35,I$43,Risks!$M$6:$M$35,Settings!$C$44) -> 0 | J38: =COUNTIFS(Risks!$I$6:$I$35,$H38,Risks!$J$6:$J$35,J$43,Risks!$M$6:$M$35,Settings!$C$44) -> 0 | K38: =COUNTIFS(Risks!$I$6:$I$35,$H38,Risks!$J$6:$J$35,K$43,Risks!$M$6:$M$35,Settings!$C$44) -> 1 | L38: =COUNTIFS(Risks!$I$6:$I$35,$H38,Risks!$J$6:$J$35,L$43,Risks!$M$6:$M$35,Settings!$C$44) -> 0 | M38: =COUNTIFS(Risks!$I$6:$I$35,$H38,Risks!$J$6:$J$35,M$43,Risks!$M$6:$M$35,Settings!$C$44) -> 0 | P38: =Settings!$C$39 -> Accepted | Q38: =COUNTIF(Deliverables!$G$6:$G$35,Settings!$C$39) -> 3
H39: 4 | I39: =COUNTIFS(Risks!$I$6:$I$35,$H39,Risks!$J$6:$J$35,I$43,Risks!$M$6:$M$35,Settings!$C$44) -> 0 | J39: =COUNTIFS(Risks!$I$6:$I$35,$H39,Risks!$J$6:$J$35,J$43,Risks!$M$6:$M$35,Settings!$C$44) -> 0 | K39: =COUNTIFS(Risks!$I$6:$I$35,$H39,Risks!$J$6:$J$35,K$43,Risks!$M$6:$M$35,Settings!$C$44) -> 0 | L39: =COUNTIFS(Risks!$I$6:$I$35,$H39,Risks!$J$6:$J$35,L$43,Risks!$M$6:$M$35,Settings!$C$44) -> 1 | M39: =COUNTIFS(Risks!$I$6:$I$35,$H39,Risks!$J$6:$J$35,M$43,Risks!$M$6:$M$35,Settings!$C$44) -> 0 | P39: =Settings!$C$38 -> Returned | Q39: =COUNTIF(Deliverables!$G$6:$G$35,Settings!$C$38) -> 1
H40: 3 | I40: =COUNTIFS(Risks!$I$6:$I$35,$H40,Risks!$J$6:$J$35,I$43,Risks!$M$6:$M$35,Settings!$C$44) -> 0 | J40: =COUNTIFS(Risks!$I$6:$I$35,$H40,Risks!$J$6:$J$35,J$43,Risks!$M$6:$M$35,Settings!$C$44) -> 0 | K40: =COUNTIFS(Risks!$I$6:$I$35,$H40,Risks!$J$6:$J$35,K$43,Risks!$M$6:$M$35,Settings!$C$44) -> 1 | L40: =COUNTIFS(Risks!$I$6:$I$35,$H40,Risks!$J$6:$J$35,L$43,Risks!$M$6:$M$35,Settings!$C$44) -> 0 | M40: =COUNTIFS(Risks!$I$6:$I$35,$H40,Risks!$J$6:$J$35,M$43,Risks!$M$6:$M$35,Settings!$C$44) -> 0 | P40: =Settings!$C$37 -> Pending | Q40: =COUNTIF(Deliverables!$G$6:$G$35,Settings!$C$37) -> 1
H41: 2 | I41: =COUNTIFS(Risks!$I$6:$I$35,$H41,Risks!$J$6:$J$35,I$43,Risks!$M$6:$M$35,Settings!$C$44) -> 0 | J41: =COUNTIFS(Risks!$I$6:$I$35,$H41,Risks!$J$6:$J$35,J$43,Risks!$M$6:$M$35,Settings!$C$44) -> 0 | K41: =COUNTIFS(Risks!$I$6:$I$35,$H41,Risks!$J$6:$J$35,K$43,Risks!$M$6:$M$35,Settings!$C$44) -> 1 | L41: =COUNTIFS(Risks!$I$6:$I$35,$H41,Risks!$J$6:$J$35,L$43,Risks!$M$6:$M$35,Settings!$C$44) -> 1 | M41: =COUNTIFS(Risks!$I$6:$I$35,$H41,Risks!$J$6:$J$35,M$43,Risks!$M$6:$M$35,Settings!$C$44) -> 0 | P41: =Settings!$C$36 -> Not delivered | Q41: =COUNTIF(Deliverables!$G$6:$G$35,Settings!$C$36) -> 3
H42: 1 | I42: =COUNTIFS(Risks!$I$6:$I$35,$H42,Risks!$J$6:$J$35,I$43,Risks!$M$6:$M$35,Settings!$C$44) -> 0 | J42: =COUNTIFS(Risks!$I$6:$I$35,$H42,Risks!$J$6:$J$35,J$43,Risks!$M$6:$M$35,Settings!$C$44) -> 0 | K42: =COUNTIFS(Risks!$I$6:$I$35,$H42,Risks!$J$6:$J$35,K$43,Risks!$M$6:$M$35,Settings!$C$44) -> 0 | L42: =COUNTIFS(Risks!$I$6:$I$35,$H42,Risks!$J$6:$J$35,L$43,Risks!$M$6:$M$35,Settings!$C$44) -> 0 | M42: =COUNTIFS(Risks!$I$6:$I$35,$H42,Risks!$J$6:$J$35,M$43,Risks!$M$6:$M$35,Settings!$C$44) -> 0
I43: 1 | J43: 2 | K43: 3 | L43: 4 | M43: 5
I45: ■ Critical ■ High ■ Medium ■ Low (zones adjustable in Settings)
B47: Weekly indices · SPI, SPI(t) and CPI
B48: SPI measures value and tends to 1.00 at closing; SPI(t) measures time. 1.00 = on plan.
B62: Priority risks
B63: The 5 open risks with the highest severity.
B64: ID | C64: Description | F64: Owner | H64: Response plan | K64: Severity | L64: Level | M64: 4 fields?
B65: =IF(LARGE(Risks!$P$6:$P$35,1)=0,"",INDEX(Risks!$B$6:$B$35,MATCH(LARGE(Risks!$P$6:$P$35,1),Risks!$P$6:$P$35,0))&"") -> R-01 | C65: =IF(LARGE(Risks!$P$6:$P$35,1)=0,"",INDEX(Risks!$D$6:$D$35,MATCH(LARGE(Risks!$P$6:$P$35,1),Risks!$P$6:$P$35,0))&"") -> Maintenance window not approved in time | F65: =IF(LARGE(Risks!$P$6:$P$35,1)=0,"",INDEX(Risks!$E$6:$E$35,MATCH(LARGE(Risks!$P$6:$P$35,1),Risks!$P$6:$P$35,0))&"") -> Tech lead | H65: =IF(LARGE(Risks!$P$6:$P$35,1)=0,"",INDEX(Risks!$H$6:$H$35,MATCH(LARGE(Risks!$P$6:$P$35,1),Risks!$P$6:$P$35,0))&"") -> Escalate to client management; book an alternate window | K65: =IF(LARGE(Risks!$P$6:$P$35,1)=0,"",INDEX(Risks!$K$6:$K$35,MATCH(LARGE(Risks!$P$6:$P$35,1),Risks!$P$6:$P$35,0))) -> 16 | L65: =IF(LARGE(Risks!$P$6:$P$35,1)=0,"",INDEX(Risks!$L$6:$L$35,MATCH(LARGE(Risks!$P$6:$P$35,1),Risks!$P$6:$P$35,0))&"") -> Critical | M65: =IF(LARGE(Risks!$P$6:$P$35,1)=0,"",INDEX(Risks!$N$6:$N$35,MATCH(LARGE(Risks!$P$6:$P$35,1),Risks!$P$6:$P$35,0))&"") -> Yes
B66: =IF(LARGE(Risks!$P$6:$P$35,2)=0,"",INDEX(Risks!$B$6:$B$35,MATCH(LARGE(Risks!$P$6:$P$35,2),Risks!$P$6:$P$35,0))&"") -> P-01 | C66: =IF(LARGE(Risks!$P$6:$P$35,2)=0,"",INDEX(Risks!$D$6:$D$35,MATCH(LARGE(Risks!$P$6:$P$35,2),Risks!$P$6:$P$35,0))&"") -> Key user unavailable for testing | F66: =IF(LARGE(Risks!$P$6:$P$35,2)=0,"",INDEX(Risks!$E$6:$E$35,MATCH(LARGE(Risks!$P$6:$P$35,2),Risks!$P$6:$P$35,0))&"") -> PM | H66: =IF(LARGE(Risks!$P$6:$P$35,2)=0,"",INDEX(Risks!$H$6:$H$35,MATCH(LARGE(Risks!$P$6:$P$35,2),Risks!$P$6:$P$35,0))&"") -> Agree on a substitute with the sponsor | K66: =IF(LARGE(Risks!$P$6:$P$35,2)=0,"",INDEX(Risks!$K$6:$K$35,MATCH(LARGE(Risks!$P$6:$P$35,2),Risks!$P$6:$P$35,0))) -> 15 | L66: =IF(LARGE(Risks!$P$6:$P$35,2)=0,"",INDEX(Risks!$L$6:$L$35,MATCH(LARGE(Risks!$P$6:$P$35,2),Risks!$P$6:$P$35,0))&"") -> Critical | M66: =IF(LARGE(Risks!$P$6:$P$35,2)=0,"",INDEX(Risks!$N$6:$N$35,MATCH(LARGE(Risks!$P$6:$P$35,2),Risks!$P$6:$P$35,0))&"") -> Yes
B67: =IF(LARGE(Risks!$P$6:$P$35,3)=0,"",INDEX(Risks!$B$6:$B$35,MATCH(LARGE(Risks!$P$6:$P$35,3),Risks!$P$6:$P$35,0))&"") -> R-02 | C67: =IF(LARGE(Risks!$P$6:$P$35,3)=0,"",INDEX(Risks!$D$6:$D$35,MATCH(LARGE(Risks!$P$6:$P$35,3),Risks!$P$6:$P$35,0))&"") -> Vendor licenses not delivered | F67: =IF(LARGE(Risks!$P$6:$P$35,3)=0,"",INDEX(Risks!$E$6:$E$35,MATCH(LARGE(Risks!$P$6:$P$35,3),Risks!$P$6:$P$35,0))&"") | H67: =IF(LARGE(Risks!$P$6:$P$35,3)=0,"",INDEX(Risks!$H$6:$H$35,MATCH(LARGE(Risks!$P$6:$P$35,3),Risks!$P$6:$P$35,0))&"") -> Request temporary licenses | K67: =IF(LARGE(Risks!$P$6:$P$35,3)=0,"",INDEX(Risks!$K$6:$K$35,MATCH(LARGE(Risks!$P$6:$P$35,3),Risks!$P$6:$P$35,0))) -> 9 | L67: =IF(LARGE(Risks!$P$6:$P$35,3)=0,"",INDEX(Risks!$L$6:$L$35,MATCH(LARGE(Risks!$P$6:$P$35,3),Risks!$P$6:$P$35,0))&"") -> High | M67: =IF(LARGE(Risks!$P$6:$P$35,3)=0,"",INDEX(Risks!$N$6:$N$35,MATCH(LARGE(Risks!$P$6:$P$35,3),Risks!$P$6:$P$35,0))&"") -> No
B68: =IF(LARGE(Risks!$P$6:$P$35,4)=0,"",INDEX(Risks!$B$6:$B$35,MATCH(LARGE(Risks!$P$6:$P$35,4),Risks!$P$6:$P$35,0))&"") -> R-04 | C68: =IF(LARGE(Risks!$P$6:$P$35,4)=0,"",INDEX(Risks!$D$6:$D$35,MATCH(LARGE(Risks!$P$6:$P$35,4),Risks!$P$6:$P$35,0))&"") -> Delay in purchasing additional storage | F68: =IF(LARGE(Risks!$P$6:$P$35,4)=0,"",INDEX(Risks!$E$6:$E$35,MATCH(LARGE(Risks!$P$6:$P$35,4),Risks!$P$6:$P$35,0))&"") -> Procurement | H68: =IF(LARGE(Risks!$P$6:$P$35,4)=0,"",INDEX(Risks!$H$6:$H$35,MATCH(LARGE(Risks!$P$6:$P$35,4),Risks!$P$6:$P$35,0))&"") -> Escalate to procurement leadership | K68: =IF(LARGE(Risks!$P$6:$P$35,4)=0,"",INDEX(Risks!$K$6:$K$35,MATCH(LARGE(Risks!$P$6:$P$35,4),Risks!$P$6:$P$35,0))) -> 8 | L68: =IF(LARGE(Risks!$P$6:$P$35,4)=0,"",INDEX(Risks!$L$6:$L$35,MATCH(LARGE(Risks!$P$6:$P$35,4),Risks!$P$6:$P$35,0))&"") -> High | M68: =IF(LARGE(Risks!$P$6:$P$35,4)=0,"",INDEX(Risks!$N$6:$N$35,MATCH(LARGE(Risks!$P$6:$P$35,4),Risks!$P$6:$P$35,0))&"") -> Yes
B69: =IF(LARGE(Risks!$P$6:$P$35,5)=0,"",INDEX(Risks!$B$6:$B$35,MATCH(LARGE(Risks!$P$6:$P$35,5),Risks!$P$6:$P$35,0))&"") -> R-03 | C69: =IF(LARGE(Risks!$P$6:$P$35,5)=0,"",INDEX(Risks!$D$6:$D$35,MATCH(LARGE(Risks!$P$6:$P$35,5),Risks!$P$6:$P$35,0))&"") -> Turnover in the infrastructure team | F69: =IF(LARGE(Risks!$P$6:$P$35,5)=0,"",INDEX(Risks!$E$6:$E$35,MATCH(LARGE(Risks!$P$6:$P$35,5),Risks!$P$6:$P$35,0))&"") -> PM | H69: =IF(LARGE(Risks!$P$6:$P$35,5)=0,"",INDEX(Risks!$H$6:$H$35,MATCH(LARGE(Risks!$P$6:$P$35,5),Risks!$P$6:$P$35,0))&"") -> Document and assign a backup per role | K69: =IF(LARGE(Risks!$P$6:$P$35,5)=0,"",INDEX(Risks!$K$6:$K$35,MATCH(LARGE(Risks!$P$6:$P$35,5),Risks!$P$6:$P$35,0))) -> 6 | L69: =IF(LARGE(Risks!$P$6:$P$35,5)=0,"",INDEX(Risks!$L$6:$L$35,MATCH(LARGE(Risks!$P$6:$P$35,5),Risks!$P$6:$P$35,0))&"") -> Medium | M69: =IF(LARGE(Risks!$P$6:$P$35,5)=0,"",INDEX(Risks!$N$6:$N$35,MATCH(LARGE(Risks!$P$6:$P$35,5),Risks!$P$6:$P$35,0))&"") -> Yes
B71: Decisions required from leadership
B72: The only thing you type on this sheet: what you need, from whom and by when.
B73: Decision required | F73: Owner | H73: Due date | I73: Impact if not decided
B74: Approve an alternate maintenance window | F74: Client management | H74: 46304 | I74: The migration slips 2 weeks and SPI drops below 0.90
B78: © Carlos Alberto Ruiz Brito · 14/10/2026 · Delivery con Charly Brito · carlosruizbrito.com · License CC BY 4.0 (use and adapt with attribution)

Sheet Read Me
B1: How to use this dashboard
B2: 15 minutes a week · fictitious sample data: delete it and enter your project's data
B5: Goal | C5: Answer four questions every week, on one page: are we on schedule?, is the money enough?, is the client accepting what we deliver? and which risks could change the outcome?
B6: 1 · Settings | C6: Once: project, currency, approved budget (BAC), thresholds and even the status-light and status texts. The whole workbook adjusts itself.
B7: 2 · Weekly tracking | C7: At the start: the cumulative plan for every week (baseline). Every Friday: actual progress and actual cost for the closed week. The current week is detected automatically.
B8: 3 · Deliverables | C8: Status of each deliverable: Not delivered, Pending (under review), Returned or Accepted, with the date it was sent for review.
B9: 4 · Risks | C9: Each risk or issue with owner, review date, trigger and response plan. Probability and impact from 1 to 5.
B10: 5 · Dashboard | C10: Calculates itself. Only type the decisions you need from leadership. Print or export to PDF on one landscape page.
B11: Cells | C11: Cream with blue text = input. White = formulas: do not edit them.
B12: Indicators | C12: PV = planned value to date. EV = % actual progress × total budget. AC = actual cost. SPI = EV/PV (measures value, not time). CPI = EV/AC (cost). 1.00 = on plan.
B13: SPI(t) | C13: Earned Schedule: ES = planned periods the work done is worth. SPI(t) = ES / elapsed periods; schedule gap = ES − elapsed periods. Use it especially in the final stretch, when SPI tends to 1.00.
B14: Earned value rule | C14: In Settings choose 0/100, 50/50 or % estimate. With the weights on the Deliverables sheet, the dashboard calculates verified progress and its SPI, to compare it with the progress you entered.
B15: Status light | C15: ● On track · ● At risk · ● Off track. Overall status takes the worst of the five indicators: a green dashboard with an open critical risk is not green.
B16: License | C16: CC BY 4.0: you may use, copy and adapt this template, even commercially, with attribution: Carlos Alberto Ruiz Brito · Delivery con Charly Brito · carlosruizbrito.com
B17: Version | C17: v1.1 EN · 14/10/2026 · English edition of v1.1 (SPI(t), schedule gap in time, earned value rule and weekly indices chart). Dates in DD/MM/YYYY format.
B20: © Carlos Alberto Ruiz Brito · 14/10/2026 · Delivery con Charly Brito · carlosruizbrito.com · License CC BY 4.0 (use and adapt with attribution)

Sheet Settings
B1: Settings
B2: Everything that makes the dashboard dynamic: project, currency, thresholds and texts. Cream cells = editable.
B5: Parameter | C5: Value | D5: What it does
B6: 1 · Project | F6: Currency | G6: Symbol
B7: Project | C7: Demo Project · Platform migration | D7: Name in the dashboard header (fictitious example) | F7: MXN | G7: $
B8: Client / sponsor | C8: Demo Client | D8: Fictitious example | F8: USD | G8: US$
B9: Report owner | C9: [Your name] | D9: Who signs the report | F9: EUR | G9: €
B10: Period name | C10: Week | D10: Week, Sprint, Fortnight… Used in headers and texts | F10: COP | G10: COL$
F11: CLP | G11: CLP$
B12: 2 · Currency and budget | F12: PEN | G12: S/
B13: Currency | C13: USD | D13: Pick from the currency table (column F); you can add others | F13: ARS | G13: AR$
B14: Symbol (automatic) | C14: =IFERROR(VLOOKUP(C13,$F$7:$G$16,2,0),"$") -> US$ | D14: Taken from the currency table | F14: BRL | G14: R$
B15: Total approved budget (BAC) | C15: 2400000 | D15: Earned value base: EV = % actual progress × BAC | F15: GTQ | G15: Q
B16: Show amounts in | C16: Thousands | D16: Units, Thousands or Millions (dashboard and cards) | F16: CAD | G16: C$
B17: Divisor (automatic) | C17: =IFERROR(VLOOKUP(C16,$F$19:$H$21,2,0),1) -> 1000
B18: Suffix (automatic) | C18: =IFERROR(VLOOKUP(C16,$F$19:$H$21,3,0),"") -> k | F18: Show | G18: Divisor | H18: Suffix
B19: Earned value rule | C19: 50/50 | D19: 0/100: only accepted counts · 50/50: half at start, half at acceptance · % estimate: progress reported by the owner (Deliverables sheet) | F19: Units | G19: 1
B20: 3 · Status-light thresholds | F20: Thousands | G20: 1000 | H20: k
B21: Progress: at risk from (points behind) | C21: 0.05 | D21: Delay against the baseline that triggers an alert | F21: Millions | G21: 1000000 | H21: M
B22: Progress: off track from (points behind) | C22: 0.1
B23: SPI / CPI: at risk below | C23: 0.95 | D23: 1.00 = on plan
B24: SPI / CPI: off track below | C24: 0.9
B25: Acceptance: max days under review | C25: 15 | D25: After this period, the deliverable is escalated
B26: Critical risk from severity | C26: 15 | D26: Severity = probability × impact (1–25)
B27: High risk from severity | C27: 8
B28: Medium risk from severity | C28: 4 | D28: Below = low
B30: 4 · Status-light texts
B31: Green status | C31: On track | D31: E.g. Green, OK, En línea · change the texts before entering data
B32: Yellow status | C32: At risk | D32: E.g. Amber, Yellow
B33: Red status | C33: Off track | D33: E.g. Red, Critical
B35: 5 · Deliverable statuses
B36: Not yet delivered | C36: Not delivered | D36: Change the texts BEFORE entering data
B37: Under client review | C37: Pending
B38: Returned with comments | C38: Returned
B39: Formally accepted | C39: Accepted
B41: 6 · Risks
B42: Type 1 | C42: Risk | D42: Has not happened yet
B43: Type 2 | C43: Issue | D43: Has already happened
B44: Open status | C44: Open
B45: Closed status | C45: Closed
...

Sheet Weekly Tracking
B1: Weekly tracking
B2: Enter the plan (all weeks) and actuals (closed weeks only). Earned value, SPI, CPI and SPI(t) are calculated automatically.
B5: =Settings!$C$10 -> Week | C5: Cut-off date | D5: Planned progress (cum.) | E5: Actual progress (cum.) | F5: ="Planned cost PV ("&Settings!$C$13&")" -> Planned cost PV (USD) | G5: ="Actual cost AC ("&Settings!$C$13&")" -> Actual cost AC (USD) | H5: ="Earned value EV ("&Settings!$C$13&")" -> Earned value EV (USD) | I5: SPI | J5: CPI | K5: Progress variance (pts) | L5: Status | M5: ES · earned schedule | N5: SPI(t) | O5: Schedule gap (periods) | Q5: SPI | R5: SPI(t) | S5: CPI
B6: 1 | C6: 46262 | D6: 0.03 | E6: 0.03 | F6: 72000 | G6: 72000 | H6: =IF(E6="","",E6*Settings!$C$15) -> 72000 | I6: =IF(OR(H6="",F6="",F6=0),"",H6/F6) -> 1 | J6: =IF(OR(H6="",G6="",G6=0),"",H6/G6) -> 1 | K6: =IF(E6="","",E6-D6) -> 0 | L6: =IF(E6="","",IF(OR(-K6>=Settings!$C$22,I6<Settings!$C$24,J6<Settings!$C$24),"● "&Settings!$C$33,IF(OR(-K6>=Settings!$C$21,I6<Settings!$C$23,J6<Settings!$C$23),"● "&Settings!$C$32,"● "&Settings!$C$31))) -> ● On track | M6: =IF(OR(H6="",B6=""),"",IF(COUNTIF($F$6:$F$29,"<="&H6)>=COUNT($F$6:$F$29),COUNT($F$6:$F$29),COUNTIF($F$6:$F$29,"<="&H6)+(H6-IF(COUNTIF($F$6:$F$29,"<="&H6)=0,0,INDEX($F$6:$F$29,COUNTIF($F$6:$F$29,"<="&H6))))/(INDEX($F$6:$F$29,COUNTIF($F$6:$F$29,"<="&H6)+1)-IF(COUNTIF($F$6:$F$29,"<="&H6)=0,0,INDEX($F$6:$F$29,COUNTIF($F$6:$F$29,"<="&H6)))))) -> 1 | N6: =IF(M6="","",M6/B6) -> 1 | O6: =IF(M6="","",M6-B6) -> 0 | Q6: =IF(I6="",NA(),I6) -> 1 | R6: =IF(N6="",NA(),N6) -> 1 | S6: =IF(J6="",NA(),J6) -> 1
B7: 2 | C7: 46269 | D7: 0.08 | E7: 0.08 | F7: 192000 | G7: 195000 | H7: =IF(E7="","",E7*Settings!$C$15) -> 192000 | I7: =IF(OR(H7="",F7="",F7=0),"",H7/F7) -> 1 | J7: =IF(OR(H7="",G7="",G7=0),"",H7/G7) -> 0.98461538 | K7: =IF(E7="","",E7-D7) -> 0 | L7: =IF(E7="","",IF(OR(-K7>=Settings!$C$22,I7<Settings!$C$24,J7<Settings!$C$24),"● "&Settings!$C$33,IF(OR(-K7>=Settings!$C$21,I7<Settings!$C$23,J7<Settings!$C$23),"● "&Settings!$C$32,"● "&Settings!$C$31))) -> ● On track | M7: =IF(OR(H7="",B7=""),"",IF(COUNTIF($F$6:$F$29,"<="&H7)>=COUNT($F$6:$F$29),COUNT($F$6:$F$29),COUNTIF($F$6:$F$29,"<="&H7)+(H7-IF(COUNTIF($F$6:$F$29,"<="&H7)=0,0,INDEX($F$6:$F$29,COUNTIF($F$6:$F$29,"<="&H7))))/(INDEX($F$6:$F$29,COUNTIF($F$6:$F$29,"<="&H7)+1)-IF(COUNTIF($F$6:$F$29,"<="&H7)=0,0,INDEX($F$6:$F$29,COUNTIF($F$6:$F$29,"<="&H7)))))) -> 2 | N7: =IF(M7="","",M7/B7) -> 1 | O7: =IF(M7="","",M7-B7) -> 0 | Q7: =IF(I7="",NA(),I7) -> 1 | R7: =IF(N7="",NA(),N7) -> 1 | S7: =IF(J7="",NA(),J7) -> 0.98461538
B8: 3 | C8: 46276 | D8: 0.15 | E8: 0.14 | F8: 360000 | G8: 345000 | H8: =IF(E8="","",E8*Settings!$C$15) -> 336000 | I8: =IF(OR(H8="",F8="",F8=0),"",H8/F8) -> 0.93333333 | J8: =IF(OR(H8="",G8="",G8=0),"",H8/G8) -> 0.97391304 | K8: =IF(E8="","",E8-D8) -> -0.01 | L8: =IF(E8="","",IF(OR(-K8>=Settings!$C$22,I8<Settings!$C$24,J8<Settings!$C$24),"● "&Settings!$C$33,IF(OR(-K8>=Settings!$C$21,I8<Settings!$C$23,J8<Settings!$C$23),"● "&Settings!$C$32,"● "&Settings!$C$31))) -> ● At risk | M8: =IF(OR(H8="",B8=""),"",IF(COUNTIF($F$6:$F$29,"<="&H8)>=COUNT($F$6:$F$29),COUNT($F$6:$F$29),COUNTIF($F$6:$F$29,"<="&H8)+(H8-IF(COUNTIF($F$6:$F$29,"<="&H8)=0,0,INDEX($F$6:$F$29,COUNTIF($F$6:$F$29,"<="&H8))))/(INDEX($F$6:$F$29,COUNTIF($F$6:$F$29,"<="&H8)+1)-IF(COUNTIF($F$6:$F$29,"<="&H8)=0,0,INDEX($F$6:$F$29,COUNTIF($F$6:$F$29,"<="&H8)))))) -> 2.8571429 | N8: =IF(M8="","",M8/B8) -> 0.95238095 | O8: =IF(M8="","",M8-B8) -> -0.14285714 | Q8: =IF(I8="",NA(),I8) -> 0.93333333 | R8: =IF(N8="",NA(),N8) -> 0.95238095 | S8: =IF(J8="",NA(),J8) -> 0.97391304
B9: 4 | C9: 46283 | D9: 0.24 | E9: 0.22 | F9: 576000 | G9: 540000 | H9: =IF(E9="","",E9*Settings!$C$15) -> 528000 | I9: =IF(OR(H9="",F9="",F9=0),"",H9/F9) -> 0.91666667 | J9: =IF(OR(H9="",G9="",G9=0),"",H9/G9) -> 0.97777778 | K9: =IF(E9="","",E9-D9) -> -0.02 | L9: =IF(E9="","",IF(OR(-K9>=Settings!$C$22,I9<Settings!$C$24,J9<Settings!$C$24),"● "&Settings!$C$33,IF(OR(-K9>=Settings!$C$21,I9<Settings!$C$23,J9<Settings!$C$23),"● "&Settings!$C$32,"● "&Settings!$C$31))) -> ● At risk | M9: =IF(OR(H9="",B9=""),"",IF(COUNTIF($F$6:$F$29,"<="&H9)>=COUNT($F$6:$F$29),COUNT($F$6:$F$29),COUNTIF($F$6:$F$29,"<="&H9)+(H9-IF(COUNTIF($F$6:$F$29,"<="&H9)=0,0,INDEX($F$6:$F$29,COUNTIF($F$6:$F$29,"<="&H9))))/(INDEX($F$6:$F$29,COUNTIF($F$6:$F$29,"<="&H9)+1)-IF(COUNTIF($F$6:$F$29,"<="&H9)=0,0,INDEX($F$6:$F$29,COUNTIF($F$6:$F$29,"<="&H9)))))) -> 3.7777778 | N9: =IF(M9="","",M9/B9) -> 0.94444444 | O9: =IF(M9="","",M9-B9) -> -0.22222222 | Q9: =IF(I9="",NA(),I9) -> 0.91666667 | R9: =IF(N9="",NA(),N9) -> 0.94444444 | S9: =IF(J9="",NA(),J9) -> 0.97777778
B10: 5 | C10: 46290 | D10: 0.34 | E10: 0.31 | F10: 816000 | G10: 760000 | H10: =IF(E10="","",E10*Settings!$C$15) -> 744000 | I10: =IF(OR(H10="",F10="",F10=0),"",H10/F10) -> 0.91176471 | J10: =IF(OR(H10="",G10="",G10=0),"",H10/G10) -> 0.97894737 | K10: =IF(E10="","",E10-D10) -> -0.03 | L10: =IF(E10="","",IF(OR(-K10>=Settings!$C$22,I10<Settings!$C$24,J10<Settings!$C$24),"● "&Settings!$C$33,IF(OR(-K10>=Settings!$C$21,I10<Settings!$C$23,J10<Settings!$C$23),"● "&Settings!$C$32,"● "&Settings!$C$31))) -> ● At risk | M10: =IF(OR(H10="",B10=""),"",IF(COUNTIF($F$6:$F$29,"<="&H10)>=COUNT($F$6:$F$29),COUNT($F$6:$F$29),COUNTIF($F$6:$F$29,"<="&H10)+(H10-IF(COUNTIF($F$6:$F$29,"<="&H10)=0,0,INDEX($F$6:$F$29,COUNTIF($F$6:$F$29,"<="&H10))))/(INDEX($F$6:$F$29,COUNTIF($F$6:$F$29,"<="&H10)+1)-IF(COUNTIF($F$6:$F$29,"<="&H10)=0,0,INDEX($F$6:$F$29,COUNTIF($F$6:$F$29,"<="&H10)))))) -> 4.7 | N10: =IF(M10="","",M10/B10) -> 0.94 | O10: =IF(M10="","",M10-B10) -> -0.3 | Q10: =IF(I10="",NA(),I10) -> 0.91176471 | R10: =IF(N10="",NA(),N10) -> 0.94 | S10: =IF(J10="",NA(),J10) -> 0.97894737
B11: 6 | C11: 46297 | D11: 0.45 | E11: 0.41 | F11: 1080000 | G11: 1000000 | H11: =IF(E11="","",E11*Settings!$C$15) -> 984000 | I11: =IF(OR(H11="",F11="",F11=0),"",H11/F11) -> 0.91111111 | J11: =IF(OR(H11="",G11="",G11=0),"",H11/G11) -> 0.984 | K11: =IF(E11="","",E11-D11) -> -0.04 | L11: =IF(E11="","",IF(OR(-K11>=Settings!$C$22,I11<Settings!$C$24,J11<Settings!$C$24),"● "&Settings!$C$33,IF(OR(-K11>=Settings!$C$21,I11<Settings!$C$23,J11<Settings!$C$23),"● "&Settings!$C$32,"● "&Settings!$C$31))) -> ● At risk | M11: =IF(OR(H11="",B11=""),"",IF(COUNTIF($F$6:$F$29,"<="&H11)>=COUNT($F$6:$F$29),COUNT($F$6:$F$29),COUNTIF($F$6:$F$29,"<="&H11)+(H11-IF(COUNTIF($F$6:$F$29,"<="&H11)=0,0,INDEX($F$6:$F$29,COUNTIF($F$6:$F$29,"<="&H11))))/(INDEX($F$6:$F$29,COUNTIF($F$6:$F$29,"<="&H11)+1)-IF(COUNTIF($F$6:$F$29,"<="&H11)=0,0,INDEX($F$6:$F$29,COUNTIF($F$6:$F$29,"<="&H11)))))) -> 5.6363636 | N11: =IF(M11="","",M11/B11) -> 0.93939394 | O11: =IF(M11="","",M11-B11) -> -0.36363636 | Q11: =IF(I11="",NA(),I11) -> 0.91111111 | R11: =IF(N11="",NA(),N11) -> 0.93939394 | S11: =IF(J11="",NA(),J11) -> 0.984
B12: 7 | C12: 46304 | D12: 0.56 | F12: 1344000 | H12: =IF(E12="","",E12*Settings!$C$15) | I12: =IF(OR(H12="",F12="",F12=0),"",H12/F12) | J12: =IF(OR(H12="",G12="",G12=0),"",H12/G12) | K12: =IF(E12="","",E12-D12) | L12: =IF(E12="","",IF(OR(-K12>=Settings!$C$22,I12<Settings!$C$24,J12<Settings!$C$24),"● "&Settings!$C$33,IF(OR(-K12>=Settings!$C$21,I12<Settings!$C$23,J12<Settings!$C$23),"● "&Settings!$C$32,"● "&Settings!$C$31))) | M12: =IF(OR(H12="",B12=""),"",IF(COUNTIF($F$6:$F$29,"<="&H12)>=COUNT($F$6:$F$29),COUNT($F$6:$F$29),COUNTIF($F$6:$F$29,"<="&H12)+(H12-IF(COUNTIF($F$6:$F$29,"<="&H12)=0,0,INDEX($F$6:$F$29,COUNTIF($F$6:$F$29,"<="&H12))))/(INDEX($F$6:$F$29,COUNTIF($F$6:$F$29,"<="&H12)+1)-IF(COUNTIF($F$6:$F$29,"<="&H12)=0,0,INDEX($F$6:$F$29,COUNTIF($F$6:$F$29,"<="&H12)))))) | N12: =IF(M12="","",M12/B12) | O12: =IF(M12="","",M12-B12) | Q12: =IF(I12="",NA(),I12) -> #N/A | R12: =IF(N12="",NA(),N12) -> #N/A | S12: =IF(J12="",NA(),J12) -> #N/A
B13: 8 | C13: 46311 | D13: 0.67 | F13: 1608000 | H13: =IF(E13="","",E13*Settings!$C$15) | I13: =IF(OR(H13="",F13="",F13=0),"",H13/F13) | J13: =IF(OR(H13="",G13="",G13=0),"",H13/G13) | K13: =IF(E13="","",E13-D13) | L13: =IF(E13="","",IF(OR(-K13>=Settings!$C$22,I13<Settings!$C$24,J13<Settings!$C$24),"● "&Settings!$C$33,IF(OR(-K13>=Settings!$C$21,I13<Settings!$C$23,J13<Settings!$C$23),"● "&Settings!$C$32,"● "&Settings!$C$31))) | M13: =IF(OR(H13="",B13=""),"",IF(COUNTIF($F$6:$F$29,"<="&H13)>=COUNT($F$6:$F$29),COUNT($F$6:$F$29),COUNTIF($F$6:$F$29,"<="&H13)+(H13-IF(COUNTIF($F$6:$F$29,"<="&H13)=0,0,INDEX($F$6:$F$29,COUNTIF($F$6:$F$29,"<="&H13))))/(INDEX($F$6:$F$29,COUNTIF($F$6:$F$29,"<="&H13)+1)-IF(COUNTIF($F$6:$F$29,"<="&H13)=0,0,INDEX($F$6:$F$29,COUNTIF($F$6:$F$29,"<="&H13)))))) | N13: =IF(M13="","",M13/B13) | O13: =IF(M13="","",M13-B13) | Q13: =IF(I13="",NA(),I13) -> #N/A | R13: =IF(N13="",NA(),N13) -> #N/A | S13: =IF(J13="",NA(),J13) -> #N/A
B14: 9 | C14: 46318 | D14: 0.77 | F14: 1848000 | H14: =IF(E14="","",E14*Settings!$C$15) | I14: =IF(OR(H14="",F14="",F14=0),"",H14/F14) | J14: =IF(OR(H14="",G14="",G14=0),"",H14/G14) | K14: =IF(E14="","",E14-D14) | L14: =IF(E14="","",IF(OR(-K14>=Settings!$C$22,I14<Settings!$C$24,J14<Settings!$C$24),"● "&Settings!$C$33,IF(OR(-K14>=Settings!$C$21,I14<Settings!$C$23,J14<Settings!$C$23),"● "&Settings!$C$32,"● "&Settings!$C$31))) | M14: =IF(OR(H14="",B14=""),"",IF(COUNTIF($F$6:$F$29,"<="&H14)>=COUNT($F$6:$F$29),COUNT($F$6:$F$29),COUNTIF($F$6:$F$29,"<="&H14)+(H14-IF(COUNTIF($F$6:$F$29,"<="&H14)=0,0,INDEX($F$6:$F$29,COUNTIF($F$6:$F$29,"<="&H14))))/(INDEX($F$6:$F$29,COUNTIF($F$6:$F$29,"<="&H14)+1)-IF(COUNTIF($F$6:$F$29,"<="&H14)=0,0,INDEX($F$6:$F$29,COUNTIF($F$6:$F$29,"<="&H14)))))) | N14: =IF(M14="","",M14/B14) | O14: =IF(M14="","",M14-B14) | Q14: =IF(I14="",NA(),I14) -> #N/A | R14: =IF(N14="",NA(),N14) -> #N/A | S14: =IF(J14="",NA(),J14) -> #N/A
B15: 10 | C15: 46325 | D15: 0.86 | F15: 2064000 | H15: =IF(E15="","",E15*Settings!$C$15) | I15: =IF(OR(H15="",F15="",F15=0),"",H15/F15) | J15: =IF(OR(H15="",G15="",G15=0),"",H15/G15) | K15: =IF(E15="","",E15-D15) | L15: =IF(E15="","",IF(OR(-K15>=Settings!$C$22,I15<Settings!$C$24,J15<Settings!$C$24),"● "&Settings!$C$33,IF(OR(-K15>=Settings!$C$21,I15<Settings!$C$23,J15<Settings!$C$23),"● "&Settings!$C$32,"● "&Settings!$C$31))) | M15: =IF(OR(H15="",B15=""),"",IF(COUNTIF($F$6:$F$29,"<="&H15)>=COUNT($F$6:$F$29),COUNT($F$6:$F$29),COUNTIF($F$6:$F$29,"<="&H15)+(H15-IF(COUNTIF($F$6:$F$29,"<="&H15)=0,0,INDEX($F$6:$F$29,COUNTIF($F$6:$F$29,"<="&H15))))/(INDEX($F$6:$F$29,COUNTIF($F$6:$F$29,"<="&H15)+1)-IF(COUNTIF($F$6:$F$29,"<="&H15)=0,0,INDEX($F$6:$F$29,COUNTIF($F$6:$F$29,"<="&H15)))))) | N15: =IF(M15="","",M15/B15) | O15: =IF(M15="","",M15-B15) | Q15: =IF(I15="",NA(),I15) -> #N/A | R15: =IF(N15="",NA(),N15) -> #N/A | S15: =IF(J15="",NA(),J15) -> #N/A
B16: 11 | C16: 46332 | D16: 0.94 | F16: 2256000 | H16: =IF(E16="","",E16*Settings!$C$15) | I16: =IF(OR(H16="",F16="",F16=0),"",H16/F16) | J16: =IF(OR(H16="",G16="",G16=0),"",H16/G16) | K16: =IF(E16="","",E16-D16) | L16: =IF(E16="","",IF(OR(-K16>=Settings!$C$22,I16<Settings!$C$24,J16<Settings!$C$24),"● "&Settings!$C$33,IF(OR(-K16>=Settings!$C$21,I16<Settings!$C$23,J16<Settings!$C$23),"● "&Settings!$C$32,"● "&Settings!$C$31))) | M16: =IF(OR(H16="",B16=""),"",IF(COUNTIF($F$6:$F$29,"<="&H16)>=COUNT($F$6:$F$29),COUNT($F$6:$F$29),COUNTIF($F$6:$F$29,"<="&H16)+(H16-IF(COUNTIF($F$6:$F$29,"<="&H16)=0,0,INDEX($F$6:$F$29,COUNTIF($F$6:$F$29,"<="&H16))))/(INDEX($F$6:$F$29,COUNTIF($F$6:$F$29,"<="&H16)+1)-IF(COUNTIF($F$6:$F$29,"<="&H16)=0,0,INDEX($F$6:$F$29,COUNTIF($F$6:$F$29,"<="&H16)))))) | N16: =IF(M16="","",M16/B16) | O16: =IF(M16="","",M16-B16) | Q16: =IF(I16="",NA(),I16) -> #N/A | R16: =IF(N16="",NA(),N16) -> #N/A | S16: =IF(J16="",NA(),J16) -> #N/A
B17: 12 | C17: 46339 | D17: 1 | F17: 2400000 | H17: =IF(E17="","",E17*Settings!$C$15) | I17: =IF(OR(H17="",F17="",F17=0),"",H17/F17) | J17: =IF(OR(H17="",G17="",G17=0),"",H17/G17) | K17: =IF(E17="","",E17-D17) | L17: =IF(E17="","",IF(OR(-K17>=Settings!$C$22,I17<Settings!$C$24,J17<Settings!$C$24),"● "&Settings!$C$33,IF(OR(-K17>=Settings!$C$21,I17<Settings!$C$23,J17<Settings!$C$23),"● "&Settings!$C$32,"● "&Settings!$C$31))) | M17: =IF(OR(H17="",B17=""),"",IF(COUNTIF($F$6:$F$29,"<="&H17)>=COUNT($F$6:$F$29),COUNT($F$6:$F$29),COUNTIF($F$6:$F$29,"<="&H17)+(H17-IF(COUNTIF($F$6:$F$29,"<="&H17)=0,0,INDEX($F$6:$F$29,COUNTIF($F$6:$F$29,"<="&H17))))/(INDEX($F$6:$F$29,COUNTIF($F$6:$F$29,"<="&H17)+1)-IF(COUNTIF($F$6:$F$29,"<="&H17)=0,0,INDEX($F$6:$F$29,COUNTIF($F$6:$F$29,"<="&H17)))))) | N17: =IF(M17="","",M17/B17) | O17: =IF(M17="","",M17-B17) | Q17: =IF(I17="",NA(),I17) -> #N/A | R17: =IF(N17="",NA(),N17) -> #N/A | S17: =IF(J17="",NA(),J17) -> #N/A
H18: =IF(E18="","",E18*Settings!$C$15) | I18: =IF(OR(H18="",F18="",F18=0),"",H18/F18) | J18: =IF(OR(H18="",G18="",G18=0),"",H18/G18) | K18: =IF(E18="","",E18-D18) | L18: =IF(E18="","",IF(OR(-K18>=Settings!$C$22,I18<Settings!$C$24,J18<Settings!$C$24),"● "&Settings!$C$33,IF(OR(-K18>=Settings!$C$21,I18<Settings!$C$23,J18<Settings!$C$23),"● "&Settings!$C$32,"● "&Settings!$C$31))) | M18: =IF(OR(H18="",B18=""),"",IF(COUNTIF($F$6:$F$29,"<="&H18)>=COUNT($F$6:$F$29),COUNT($F$6:$F$29),COUNTIF($F$6:$F$29,"<="&H18)+(H18-IF(COUNTIF($F$6:$F$29,"<="&H18)=0,0,INDEX($F$6:$F$29,COUNTIF($F$6:$F$29,"<="&H18))))/(INDEX($F$6:$F$29,COUNTIF($F$6:$F$29,"<="&H18)+1)-IF(COUNTIF($F$6:$F$29,"<="&H18)=0,0,INDEX($F$6:$F$29,COUNTIF($F$6:$F$29,"<="&H18)))))) | N18: =IF(M18="","",M18/B18) | O18: =IF(M18="","",M18-B18) | Q18: =IF(I18="",NA(),I18) -> #N/A | R18: =IF(N18="",NA(),N18) -> #N/A | S18: =IF(J18="",NA(),J18) -> #N/A
H19: =IF(E19="","",E19*Settings!$C$15) | I19: =IF(OR(H19="",F19="",F19=0),"",H19/F19) | J19: =IF(OR(H19="",G19="",G19=0),"",H19/G19) | K19: =IF(E19="","",E19-D19) | L19: =IF(E19="","",IF(OR(-K19>=Settings!$C$22,I19<Settings!$C$24,J19<Settings!$C$24),"● "&Settings!$C$33,IF(OR(-K19>=Settings!$C$21,I19<Settings!$C$23,J19<Settings!$C$23),"● "&Settings!$C$32,"● "&Settings!$C$31))) | M19: =IF(OR(H19="",B19=""),"",IF(COUNTIF($F$6:$F$29,"<="&H19)>=COUNT($F$6:$F$29),COUNT($F$6:$F$29),COUNTIF($F$6:$F$29,"<="&H19)+(H19-IF(COUNTIF($F$6:$F$29,"<="&H19)=0,0,INDEX($F$6:$F$29,COUNTIF($F$6:$F$29,"<="&H19))))/(INDEX($F$6:$F$29,COUNTIF($F$6:$F$29,"<="&H19)+1)-IF(COUNTIF($F$6:$F$29,"<="&H19)=0,0,INDEX($F$6:$F$29,COUNTIF($F$6:$F$29,"<="&H19)))))) | N19: =IF(M19="","",M19/B19) | O19: =IF(M19="","",M19-B19) | Q19: =IF(I19="",NA(),I19) -> #N/A | R19: =IF(N19="",NA(),N19) -> #N/A | S19: =IF(J19="",NA(),J19) -> #N/A
H20: =IF(E20="","",E20*Settings!$C$15) | I20: =IF(OR(H20="",F20="",F20=0),"",H20/F20) | J20: =IF(OR(H20="",G20="",G20=0),"",H20/G20) | K20: =IF(E20="","",E20-D20) | L20: =IF(E20="","",IF(OR(-K20>=Settings!$C$22,I20<Settings!$C$24,J20<Settings!$C$24),"● "&Settings!$C$33,IF(OR(-K20>=Settings!$C$21,I20<Settings!$C$23,J20<Settings!$C$23),"● "&Settings!$C$32,"● "&Settings!$C$31))) | M20: =IF(OR(H20="",B20=""),"",IF(COUNTIF($F$6:$F$29,"<="&H20)>=COUNT($F$6:$F$29),COUNT($F$6:$F$29),COUNTIF($F$6:$F$29,"<="&H20)+(H20-IF(COUNTIF($F$6:$F$29,"<="&H20)=0,0,INDEX($F$6:$F$29,COUNTIF($F$6:$F$29,"<="&H20))))/(INDEX($F$6:$F$29,COUNTIF($F$6:$F$29,"<="&H20)+1)-IF(COUNTIF($F$6:$F$29,"<="&H20)=0,0,INDEX($F$6:$F$29,COUNTIF($F$6:$F$29,"<="&H20)))))) | N20: =IF(M20="","",M20/B20) | O20: =IF(M20="","",M20-B20) | Q20: =IF(I20="",NA(),I20) -> #N/A | R20: =IF(N20="",NA(),N20) -> #N/A | S20: =IF(J20="",NA(),J20) -> #N/A
H21: =IF(E21="","",E21*Settings!$C$15) | I21: =IF(OR(H21="",F21="",F21=0),"",H21/F21) | J21: =IF(OR(H21="",G21="",G21=0),"",H21/G21) | K21: =IF(E21="","",E21-D21) | L21: =IF(E21="","",IF(OR(-K21>=Settings!$C$22,I21<Settings!$C$24,J21<Settings!$C$24),"● "&Settings!$C$33,IF(OR(-K21>=Settings!$C$21,I21<Settings!$C$23,J21<Settings!$C$23),"● "&Settings!$C$32,"● "&Settings!$C$31))) | M21: =IF(OR(H21="",B21=""),"",IF(COUNTIF($F$6:$F$29,"<="&H21)>=COUNT($F$6:$F$29),COUNT($F$6:$F$29),COUNTIF($F$6:$F$29,"<="&H21)+(H21-IF(COUNTIF($F$6:$F$29,"<="&H21)=0,0,INDEX($F$6:$F$29,COUNTIF($F$6:$F$29,"<="&H21))))/(INDEX($F$6:$F$29,COUNTIF($F$6:$F$29,"<="&H21)+1)-IF(COUNTIF($F$6:$F$29,"<="&H21)=0,0,INDEX($F$6:$F$29,COUNTIF($F$6:$F$29,"<="&H21)))))) | N21: =IF(M21="","",M21/B21) | O21: =IF(M21="","",M21-B21) | Q21: =IF(I21="",NA(),I21) -> #N/A | R21: =IF(N21="",NA(),N21) -> #N/A | S21: =IF(J21="",NA(),J21) -> #N/A
H22: =IF(E22="","",E22*Settings!$C$15) | I22: =IF(OR(H22="",F22="",F22=0),"",H22/F22) | J22: =IF(OR(H22="",G22="",G22=0),"",H22/G22) | K22: =IF(E22="","",E22-D22) | L22: =IF(E22="","",IF(OR(-K22>=Settings!$C$22,I22<Settings!$C$24,J22<Settings!$C$24),"● "&Settings!$C$33,IF(OR(-K22>=Settings!$C$21,I22<Settings!$C$23,J22<Settings!$C$23),"● "&Settings!$C$32,"● "&Settings!$C$31))) | M22: =IF(OR(H22="",B22=""),"",IF(COUNTIF($F$6:$F$29,"<="&H22)>=COUNT($F$6:$F$29),COUNT($F$6:$F$29),COUNTIF($F$6:$F$29,"<="&H22)+(H22-IF(COUNTIF($F$6:$F$29,"<="&H22)=0,0,INDEX($F$6:$F$29,COUNTIF($F$6:$F$29,"<="&H22))))/(INDEX($F$6:$F$29,COUNTIF($F$6:$F$29,"<="&H22)+1)-IF(COUNTIF($F$6:$F$29,"<="&H22)=0,0,INDEX($F$6:$F$29,COUNTIF($F$6:$F$29,"<="&H22)))))) | N22: =IF(M22="","",M22/B22) | O22: =IF(M22="","",M22-B22) | Q22: =IF(I22="",NA(),I22) -> #N/A | R22: =IF(N22="",NA(),N22) -> #N/A | S22: =IF(J22="",NA(),J22) -> #N/A
H23: =IF(E23="","",E23*Settings!$C$15) | I23: =IF(OR(H23="",F23="",F23=0),"",H23/F23) | J23: =IF(OR(H23="",G23="",G23=0),"",H23/G23) | K23: =IF(E23="","",E23-D23) | L23: =IF(E23="","",IF(OR(-K23>=Settings!$C$22,I23<Settings!$C$24,J23<Settings!$C$24),"● "&Settings!$C$33,IF(OR(-K23>=Settings!$C$21,I23<Settings!$C$23,J23<Settings!$C$23),"● "&Settings!$C$32,"● "&Settings!$C$31))) | M23: =IF(OR(H23="",B23=""),"",IF(COUNTIF($F$6:$F$29,"<="&H23)>=COUNT($F$6:$F$29),COUNT($F$6:$F$29),COUNTIF($F$6:$F$29,"<="&H23)+(H23-IF(COUNTIF($F$6:$F$29,"<="&H23)=0,0,INDEX($F$6:$F$29,COUNTIF($F$6:$F$29,"<="&H23))))/(INDEX($F$6:$F$29,COUNTIF($F$6:$F$29,"<="&H23)+1)-IF(COUNTIF($F$6:$F$29,"<="&H23)=0,0,INDEX($F$6:$F$29,COUNTIF($F$6:$F$29,"<="&H23)))))) | N23: =IF(M23="","",M23/B23) | O23: =IF(M23="","",M23-B23) | Q23: =IF(I23="",NA(),I23) -> #N/A | R23: =IF(N23="",NA(),N23) -> #N/A | S23: =IF(J23="",NA(),J23) -> #N/A
H24: =IF(E24="","",E24*Settings!$C$15) | I24: =IF(OR(H24="",F24="",F24=0),"",H24/F24) | J24: =IF(OR(H24="",G24="",G24=0),"",H24/G24) | K24: =IF(E24="","",E24-D24) | L24: =IF(E24="","",IF(OR(-K24>=Settings!$C$22,I24<Settings!$C$24,J24<Settings!$C$24),"● "&Settings!$C$33,IF(OR(-K24>=Settings!$C$21,I24<Settings!$C$23,J24<Settings!$C$23),"● "&Settings!$C$32,"● "&Settings!$C$31))) | M24: =IF(OR(H24="",B24=""),"",IF(COUNTIF($F$6:$F$29,"<="&H24)>=COUNT($F$6:$F$29),COUNT($F$6:$F$29),COUNTIF($F$6:$F$29,"<="&H24)+(H24-IF(COUNTIF($F$6:$F$29,"<="&H24)=0,0,INDEX($F$6:$F$29,COUNTIF($F$6:$F$29,"<="&H24))))/(INDEX($F$6:$F$29,COUNTIF($F$6:$F$29,"<="&H24)+1)-IF(COUNTIF($F$6:$F$29,"<="&H24)=0,0,INDEX($F$6:$F$29,COUNTIF($F$6:$F$29,"<="&H24)))))) | N24: =IF(M24="","",M24/B24) | O24: =IF(M24="","",M24-B24) | Q24: =IF(I24="",NA(),I24) -> #N/A | R24: =IF(N24="",NA(),N24) -> #N/A | S24: =IF(J24="",NA(),J24) -> #N/A
H25: =IF(E25="","",E25*Settings!$C$15) | I25: =IF(OR(H25="",F25="",F25=0),"",H25/F25) | J25: =IF(OR(H25="",G25="",G25=0),"",H25/G25) | K25: =IF(E25="","",E25-D25) | L25: =IF(E25="","",IF(OR(-K25>=Settings!$C$22,I25<Settings!$C$24,J25<Settings!$C$24),"● "&Settings!$C$33,IF(OR(-K25>=Settings!$C$21,I25<Settings!$C$23,J25<Settings!$C$23),"● "&Settings!$C$32,"● "&Settings!$C$31))) | M25: =IF(OR(H25="",B25=""),"",IF(COUNTIF($F$6:$F$29,"<="&H25)>=COUNT($F$6:$F$29),COUNT($F$6:$F$29),COUNTIF($F$6:$F$29,"<="&H25)+(H25-IF(COUNTIF($F$6:$F$29,"<="&H25)=0,0,INDEX($F$6:$F$29,COUNTIF($F$6:$F$29,"<="&H25))))/(INDEX($F$6:$F$29,COUNTIF($F$6:$F$29,"<="&H25)+1)-IF(COUNTIF($F$6:$F$29,"<="&H25)=0,0,INDEX($F$6:$F$29,COUNTIF($F$6:$F$29,"<="&H25)))))) | N25: =IF(M25="","",M25/B25) | O25: =IF(M25="","",M25-B25) | Q25: =IF(I25="",NA(),I25) -> #N/A | R25: =IF(N25="",NA(),N25) -> #N/A | S25: =IF(J25="",NA(),J25) -> #N/A
H26: =IF(E26="","",E26*Settings!$C$15) | I26: =IF(OR(H26="",F26="",F26=0),"",H26/F26) | J26: =IF(OR(H26="",G26="",G26=0),"",H26/G26) | K26: =IF(E26="","",E26-D26) | L26: =IF(E26="","",IF(OR(-K26>=Settings!$C$22,I26<Settings!$C$24,J26<Settings!$C$24),"● "&Settings!$C$33,IF(OR(-K26>=Settings!$C$21,I26<Settings!$C$23,J26<Settings!$C$23),"● "&Settings!$C$32,"● "&Settings!$C$31))) | M26: =IF(OR(H26="",B26=""),"",IF(COUNTIF($F$6:$F$29,"<="&H26)>=COUNT($F$6:$F$29),COUNT($F$6:$F$29),COUNTIF($F$6:$F$29,"<="&H26)+(H26-IF(COUNTIF($F$6:$F$29,"<="&H26)=0,0,INDEX($F$6:$F$29,COUNTIF($F$6:$F$29,"<="&H26))))/(INDEX($F$6:$F$29,COUNTIF($F$6:$F$29,"<="&H26)+1)-IF(COUNTIF($F$6:$F$29,"<="&H26)=0,0,INDEX($F$6:$F$29,COUNTIF($F$6:$F$29,"<="&H26)))))) | N26: =IF(M26="","",M26/B26) | O26: =IF(M26="","",M26-B26) | Q26: =IF(I26="",NA(),I26) -> #N/A | R26: =IF(N26="",NA(),N26) -> #N/A | S26: =IF(J26="",NA(),J26) -> #N/A
H27: =IF(E27="","",E27*Settings!$C$15) | I27: =IF(OR(H27="",F27="",F27=0),"",H27/F27) | J27: =IF(OR(H27="",G27="",G27=0),"",H27/G27) | K27: =IF(E27="","",E27-D27) | L27: =IF(E27="","",IF(OR(-K27>=Settings!$C$22,I27<Settings!$C$24,J27<Settings!$C$24),"● "&Settings!$C$33,IF(OR(-K27>=Settings!$C$21,I27<Settings!$C$23,J27<Settings!$C$23),"● "&Settings!$C$32,"● "&Settings!$C$31))) | M27: =IF(OR(H27="",B27=""),"",IF(COUNTIF($F$6:$F$29,"<="&H27)>=COUNT($F$6:$F$29),COUNT($F$6:$F$29),COUNTIF($F$6:$F$29,"<="&H27)+(H27-IF(COUNTIF($F$6:$F$29,"<="&H27)=0,0,INDEX($F$6:$F$29,COUNTIF($F$6:$F$29,"<="&H27))))/(INDEX($F$6:$F$29,COUNTIF($F$6:$F$29,"<="&H27)+1)-IF(COUNTIF($F$6:$F$29,"<="&H27)=0,0,INDEX($F$6:$F$29,COUNTIF($F$6:$F$29,"<="&H27)))))) | N27: =IF(M27="","",M27/B27) | O27: =IF(M27="","",M27-B27) | Q27: =IF(I27="",NA(),I27) -> #N/A | R27: =IF(N27="",NA(),N27) -> #N/A | S27: =IF(J27="",NA(),J27) -> #N/A
H28: =IF(E28="","",E28*Settings!$C$15) | I28: =IF(OR(H28="",F28="",F28=0),"",H28/F28) | J28: =IF(OR(H28="",G28="",G28=0),"",H28/G28) | K28: =IF(E28="","",E28-D28) | L28: =IF(E28="","",IF(OR(-K28>=Settings!$C$22,I28<Settings!$C$24,J28<Settings!$C$24),"● "&Settings!$C$33,IF(OR(-K28>=Settings!$C$21,I28<Settings!$C$23,J28<Settings!$C$23),"● "&Settings!$C$32,"● "&Settings!$C$31))) | M28: =IF(OR(H28="",B28=""),"",IF(COUNTIF($F$6:$F$29,"<="&H28)>=COUNT($F$6:$F$29),COUNT($F$6:$F$29),COUNTIF($F$6:$F$29,"<="&H28)+(H28-IF(COUNTIF($F$6:$F$29,"<="&H28)=0,0,INDEX($F$6:$F$29,COUNTIF($F$6:$F$29,"<="&H28))))/(INDEX($F$6:$F$29,COUNTIF($F$6:$F$29,"<="&H28)+1)-IF(COUNTIF($F$6:$F$29,"<="&H28)=0,0,INDEX($F$6:$F$29,COUNTIF($F$6:$F$29,"<="&H28)))))) | N28: =IF(M28="","",M28/B28) | O28: =IF(M28="","",M28-B28) | Q28: =IF(I28="",NA(),I28) -> #N/A | R28: =IF(N28="",NA(),N28) -> #N/A | S28: =IF(J28="",NA(),J28) -> #N/A
H29: =IF(E29="","",E29*Settings!$C$15) | I29: =IF(OR(H29="",F29="",F29=0),"",H29/F29) | J29: =IF(OR(H29="",G29="",G29=0),"",H29/G29) | K29: =IF(E29="","",E29-D29) | L29: =IF(E29="","",IF(OR(-K29>=Settings!$C$22,I29<Settings!$C$24,J29<Settings!$C$24),"● "&Settings!$C$33,IF(OR(-K29>=Settings!$C$21,I29<Settings!$C$23,J29<Settings!$C$23),"● "&Settings!$C$32,"● "&Settings!$C$31))) | M29: =IF(OR(H29="",B29=""),"",IF(COUNTIF($F$6:$F$29,"<="&H29)>=COUNT($F$6:$F$29),COUNT($F$6:$F$29),COUNTIF($F$6:$F$29,"<="&H29)+(H29-IF(COUNTIF($F$6:$F$29,"<="&H29)=0,0,INDEX($F$6:$F$29,COUNTIF($F$6:$F$29,"<="&H29))))/(INDEX($F$6:$F$29,COUNTIF($F$6:$F$29,"<="&H29)+1)-IF(COUNTIF($F$6:$F$29,"<="&H29)=0,0,INDEX($F$6:$F$29,COUNTIF($F$6:$F$29,"<="&H29)))))) | N29: =IF(M29="","",M29/B29) | O29: =IF(M29="","",M29-B29) | Q29: =IF(I29="",NA(),I29) -> #N/A | R29: =IF(N29="",NA(),N29) -> #N/A | S29: =IF(J29="",NA(),J29) -> #N/A
B31: SPI = EV / PV (value) · CPI = EV / AC (cost) · ES = planned periods the work done is worth · SPI(t) = ES / elapsed periods (time) · Gap = ES − elapsed periods
B32: © Carlos Alberto Ruiz Brito · 14/10/2026 · Delivery con Charly Brito · carlosruizbrito.com · License CC BY 4.0 (use and adapt with attribution)

Sheet Deliverables
B1: Deliverables and acceptance
B2: Delivered is not accepted: each deliverable with its status, days under review and its contribution to earned value under the chosen rule.
B5: ID | C5: Deliverable | D5: Owner | E5: Committed date | F5: Sent for review | G5: Status | H5: Acceptance date | I5: Days under review | J5: Delay vs. commitment | K5: Comment | L5: Weight (% of total) | M5: Estimated progress | N5: Contribution per rule
B6: E-01 | C6: Solution design | D6: Architect | E6: 46269 | F6: 46268 | G6: Accepted | H6: 46273 | I6: =IF(OR(F6="",G6=Settings!$C$39,G6=Settings!$C$36),"",INDEX('Weekly Tracking'!$C$6:$C$29,COUNT('Weekly Tracking'!$E$6:$E$29))-F6) | J6: =IF(OR(E6="",F6=""),"",MAX(0,F6-E6)) -> 0 | K6: Signed sign-off | L6: 0.05 | M6: 1 | N6: =IF(L6="","",L6*IF(G6=Settings!$C$39,1,IF(Settings!$C$19="0/100",0,IF(Settings!$C$19="50/50",IF(OR(M6>0,AND(G6<>"",G6<>Settings!$C$36)),0.5,0),MIN(1,M6))))) -> 0.05
B7: E-02 | C7: Work plan and baseline | D7: PM | E7: 46269 | F7: 46269 | G7: Accepted | H7: 46272 | I7: =IF(OR(F7="",G7=Settings!$C$39,G7=Settings!$C$36),"",INDEX('Weekly Tracking'!$C$6:$C$29,COUNT('Weekly Tracking'!$E$6:$E$29))-F7) | J7: =IF(OR(E7="",F7=""),"",MAX(0,F7-E7)) -> 0 | L7: 0.05 | M7: 1 | N7: =IF(L7="","",L7*IF(G7=Settings!$C$39,1,IF(Settings!$C$19="0/100",0,IF(Settings!$C$19="50/50",IF(OR(M7>0,AND(G7<>"",G7<>Settings!$C$36)),0.5,0),MIN(1,M7))))) -> 0.05
B8: E-03 | C8: Inventory and dependencies | D8: Tech lead | E8: 46276 | F8: 46279 | G8: Accepted | H8: 46283 | I8: =IF(OR(F8="",G8=Settings!$C$39,G8=Settings!$C$36),"",INDEX('Weekly Tracking'!$C$6:$C$29,COUNT('Weekly Tracking'!$E$6:$E$29))-F8) | J8: =IF(OR(E8="",F8=""),"",MAX(0,F8-E8)) -> 3 | K8: Delivered 3 days late | L8: 0.1 | M8: 1 | N8: =IF(L8="","",L8*IF(G8=Settings!$C$39,1,IF(Settings!$C$19="0/100",0,IF(Settings!$C$19="50/50",IF(OR(M8>0,AND(G8<>"",G8<>Settings!$C$36)),0.5,0),MIN(1,M8))))) -> 0.1
B9: E-04 | C9: Migration plan | D9: Tech lead | E9: 46290 | F9: 46290 | G9: Returned | I9: =IF(OR(F9="",G9=Settings!$C$39,G9=Settings!$C$36),"",INDEX('Weekly Tracking'!$C$6:$C$29,COUNT('Weekly Tracking'!$E$6:$E$29))-F9) -> 7 | J9: =IF(OR(E9="",F9=""),"",MAX(0,F9-E9)) -> 0 | K9: 2 client comments | L9: 0.1 | M9: 1 | N9: =IF(L9="","",L9*IF(G9=Settings!$C$39,1,IF(Settings!$C$19="0/100",0,IF(Settings!$C$19="50/50",IF(OR(M9>0,AND(G9<>"",G9<>Settings!$C$36)),0.5,0),MIN(1,M9))))) -> 0.05
B10: E-05 | C10: Test environment | D10: Infrastructure | E10: 46276 | F10: 46276 | G10: Pending | I10: =IF(OR(F10="",G10=Settings!$C$39,G10=Settings!$C$36),"",INDEX('Weekly Tracking'!$C$6:$C$29,COUNT('Weekly Tracking'!$E$6:$E$29))-F10) -> 21 | J10: =IF(OR(E10="",F10=""),"",MAX(0,F10-E10)) -> 0 | K10: No response from key user | L10: 0.1 | M10: 1 | N10: =IF(L10="","",L10*IF(G10=Settings!$C$39,1,IF(Settings!$C$19="0/100",0,IF(Settings!$C$19="50/50",IF(OR(M10>0,AND(G10<>"",G10<>Settings!$C$36)),0.5,0),MIN(1,M10))))) -> 0.05
B11: E-06 | C11: Recovery testing (DR) | D11: Infrastructure | E11: 46311 | G11: Not delivered | I11: =IF(OR(F11="",G11=Settings!$C$39,G11=Settings!$C$36),"",INDEX('Weekly Tracking'!$C$6:$C$29,COUNT('Weekly Tracking'!$E$6:$E$29))-F11) | J11: =IF(OR(E11="",F11=""),"",MAX(0,F11-E11)) | L11: 0.2 | M11: 0.1 | N11: =IF(L11="","",L11*IF(G11=Settings!$C$39,1,IF(Settings!$C$19="0/100",0,IF(Settings!$C$19="50/50",IF(OR(M11>0,AND(G11<>"",G11<>Settings!$C$36)),0.5,0),MIN(1,M11))))) -> 0.1
B12: E-07 | C12: Rollback plan | D12: Tech lead | E12: 46318 | G12: Not delivered | I12: =IF(OR(F12="",G12=Settings!$C$39,G12=Settings!$C$36),"",INDEX('Weekly Tracking'!$C$6:$C$29,COUNT('Weekly Tracking'!$E$6:$E$29))-F12) | J12: =IF(OR(E12="",F12=""),"",MAX(0,F12-E12)) | L12: 0.15 | M12: 0 | N12: =IF(L12="","",L12*IF(G12=Settings!$C$39,1,IF(Settings!$C$19="0/100",0,IF(Settings!$C$19="50/50",IF(OR(M12>0,AND(G12<>"",G12<>Settings!$C$36)),0.5,0),MIN(1,M12))))) -> 0
B13: E-08 | C13: Closure sign-off | D13: PM | E13: 46339 | G13: Not delivered | I13: =IF(OR(F13="",G13=Settings!$C$39,G13=Settings!$C$36),"",INDEX('Weekly Tracking'!$C$6:$C$29,COUNT('Weekly Tracking'!$E$6:$E$29))-F13) | J13: =IF(OR(E13="",F13=""),"",MAX(0,F13-E13)) | L13: 0.25 | M13: 0 | N13: =IF(L13="","",L13*IF(G13=Settings!$C$39,1,IF(Settings!$C$19="0/100",0,IF(Settings!$C$19="50/50",IF(OR(M13>0,AND(G13<>"",G13<>Settings!$C$36)),0.5,0),MIN(1,M13))))) -> 0
I14: =IF(OR(F14="",G14=Settings!$C$39,G14=Settings!$C$36),"",INDEX('Weekly Tracking'!$C$6:$C$29,COUNT('Weekly Tracking'!$E$6:$E$29))-F14) | J14: =IF(OR(E14="",F14=""),"",MAX(0,F14-E14)) | N14: =IF(L14="","",L14*IF(G14=Settings!$C$39,1,IF(Settings!$C$19="0/100",0,IF(Settings!$C$19="50/50",IF(OR(M14>0,AND(G14<>"",G14<>Settings!$C$36)),0.5,0),MIN(1,M14)))))
I15: =IF(OR(F15="",G15=Settings!$C$39,G15=Settings!$C$36),"",INDEX('Weekly Tracking'!$C$6:$C$29,COUNT('Weekly Tracking'!$E$6:$E$29))-F15) | J15: =IF(OR(E15="",F15=""),"",MAX(0,F15-E15)) | N15: =IF(L15="","",L15*IF(G15=Settings!$C$39,1,IF(Settings!$C$19="0/100",0,IF(Settings!$C$19="50/50",IF(OR(M15>0,AND(G15<>"",G15<>Settings!$C$36)),0.5,0),MIN(1,M15)))))
I16: =IF(OR(F16="",G16=Settings!$C$39,G16=Settings!$C$36),"",INDEX('Weekly Tracking'!$C$6:$C$29,COUNT('Weekly Tracking'!$E$6:$E$29))-F16) | J16: =IF(OR(E16="",F16=""),"",MAX(0,F16-E16)) | N16: =IF(L16="","",L16*IF(G16=Settings!$C$39,1,IF(Settings!$C$19="0/100",0,IF(Settings!$C$19="50/50",IF(OR(M16>0,AND(G16<>"",G16<>Settings!$C$36)),0.5,0),MIN(1,M16)))))
I17: =IF(OR(F17="",G17=Settings!$C$39,G17=Settings!$C$36),"",INDEX('Weekly Tracking'!$C$6:$C$29,COUNT('Weekly Tracking'!$E$6:$E$29))-F17) | J17: =IF(OR(E17="",F17=""),"",MAX(0,F17-E17)) | N17: =IF(L17="","",L17*IF(G17=Settings!$C$39,1,IF(Settings!$C$19="0/100",0,IF(Settings!$C$19="50/50",IF(OR(M17>0,AND(G17<>"",G17<>Settings!$C$36)),0.5,0),MIN(1,M17)))))
I18: =IF(OR(F18="",G18=Settings!$C$39,G18=Settings!$C$36),"",INDEX('Weekly Tracking'!$C$6:$C$29,COUNT('Weekly Tracking'!$E$6:$E$29))-F18) | J18: =IF(OR(E18="",F18=""),"",MAX(0,F18-E18)) | N18: =IF(L18="","",L18*IF(G18=Settings!$C$39,1,IF(Settings!$C$19="0/100",0,IF(Settings!$C$19="50/50",IF(OR(M18>0,AND(G18<>"",G18<>Settings!$C$36)),0.5,0),MIN(1,M18)))))
I19: =IF(OR(F19="",G19=Settings!$C$39,G19=Settings!$C$36),"",INDEX('Weekly Tracking'!$C$6:$C$29,COUNT('Weekly Tracking'!$E$6:$E$29))-F19) | J19: =IF(OR(E19="",F19=""),"",MAX(0,F19-E19)) | N19: =IF(L19="","",L19*IF(G19=Settings!$C$39,1,IF(Settings!$C$19="0/100",0,IF(Settings!$C$19="50/50",IF(OR(M19>0,AND(G19<>"",G19<>Settings!$C$36)),0.5,0),MIN(1,M19)))))
I20: =IF(OR(F20="",G20=Settings!$C$39,G20=Settings!$C$36),"",INDEX('Weekly Tracking'!$C$6:$C$29,COUNT('Weekly Tracking'!$E$6:$E$29))-F20) | J20: =IF(OR(E20="",F20=""),"",MAX(0,F20-E20)) | N20: =IF(L20="","",L20*IF(G20=Settings!$C$39,1,IF(Settings!$C$19="0/100",0,IF(Settings!$C$19="50/50",IF(OR(M20>0,AND(G20<>"",G20<>Settings!$C$36)),0.5,0),MIN(1,M20)))))
I21: =IF(OR(F21="",G21=Settings!$C$39,G21=Settings!$C$36),"",INDEX('Weekly Tracking'!$C$6:$C$29,COUNT('Weekly Tracking'!$E$6:$E$29))-F21) | J21: =IF(OR(E21="",F21=""),"",MAX(0,F21-E21)) | N21: =IF(L21="","",L21*IF(G21=Settings!$C$39,1,IF(Settings!$C$19="0/100",0,IF(Settings!$C$19="50/50",IF(OR(M21>0,AND(G21<>"",G21<>Settings!$C$36)),0.5,0),MIN(1,M21)))))
I22: =IF(OR(F22="",G22=Settings!$C$39,G22=Settings!$C$36),"",INDEX('Weekly Tracking'!$C$6:$C$29,COUNT('Weekly Tracking'!$E$6:$E$29))-F22) | J22: =IF(OR(E22="",F22=""),"",MAX(0,F22-E22)) | N22: =IF(L22="","",L22*IF(G22=Settings!$C$39,1,IF(Settings!$C$19="0/100",0,IF(Settings!$C$19="50/50",IF(OR(M22>0,AND(G22<>"",G22<>Settings!$C$36)),0.5,0),MIN(1,M22)))))
I23: =IF(OR(F23="",G23=Settings!$C$39,G23=Settings!$C$36),"",INDEX('Weekly Tracking'!$C$6:$C$29,COUNT('Weekly Tracking'!$E$6:$E$29))-F23) | J23: =IF(OR(E23="",F23=""),"",MAX(0,F23-E23)) | N23: =IF(L23="","",L23*IF(G23=Settings!$C$39,1,IF(Settings!$C$19="0/100",0,IF(Settings!$C$19="50/50",IF(OR(M23>0,AND(G23<>"",G23<>Settings!$C$36)),0.5,0),MIN(1,M23)))))
I24: =IF(OR(F24="",G24=Settings!$C$39,G24=Settings!$C$36),"",INDEX('Weekly Tracking'!$C$6:$C$29,COUNT('Weekly Tracking'!$E$6:$E$29))-F24) | J24: =IF(OR(E24="",F24=""),"",MAX(0,F24-E24)) | N24: =IF(L24="","",L24*IF(G24=Settings!$C$39,1,IF(Settings!$C$19="0/100",0,IF(Settings!$C$19="50/50",IF(OR(M24>0,AND(G24<>"",G24<>Settings!$C$36)),0.5,0),MIN(1,M24)))))
I25: =IF(OR(F25="",G25=Settings!$C$39,G25=Settings!$C$36),"",INDEX('Weekly Tracking'!$C$6:$C$29,COUNT('Weekly Tracking'!$E$6:$E$29))-F25) | J25: =IF(OR(E25="",F25=""),"",MAX(0,F25-E25)) | N25: =IF(L25="","",L25*IF(G25=Settings!$C$39,1,IF(Settings!$C$19="0/100",0,IF(Settings!$C$19="50/50",IF(OR(M25>0,AND(G25<>"",G25<>Settings!$C$36)),0.5,0),MIN(1,M25)))))
... I35: =IF(OR(F35="",G35=Settings!$C$39,G35=Settings!$C$36),"",INDEX('Weekly Tracking'!$C$6:$C$29,COUNT('Weekly Tracking'!$E$6:$E$29))-F35) | J35: =IF(OR(E35="",F35=""),"",MAX(0,F35-E35)) | N35: =IF(L35="","",L35*IF(G35=Settings!$C$39,1,IF(Settings!$C$19="0/100",0,IF(Settings!$C$19="50/50",IF(OR(M35>0,AND(G35<>"",G35<>Settings!$C$36)),0.5,0),MIN(1,M35)))))
K36: Totals | L36: =SUM(L6:L35) -> 1 | N36: =SUM(N6:N35) -> 0.4
K37: Weights must add up to 100%. The contribution depends on the earned value rule (Settings).
B39: © Carlos Alberto Ruiz Brito · 14/10/2026 · Delivery con Charly Brito · carlosruizbrito.com · License CC BY 4.0 (use and adapt with attribution)

Sheet Risks
B1: Risks and issues
B2: A risk is managed only if it has all 4 fields: owner, review date, trigger and response plan.
B5: ID | C5: Type | D5: Description | E5: Owner | F5: Review date | G5: Trigger | H5: Response plan | I5: Prob. (1-5) | J5: Impact (1-5) | K5: Severity | L5: Level | M5: Status | N5: 4 fields? | O5: Review overdue? | P5: key
B6: R-01 | C6: Risk | D6: Maintenance window not approved in time | E6: Tech lead | F6: 46304 | G6: No approval 5 days before | H6: Escalate to client management; book an alternate window | I6: 4 | J6: 4 | K6: =IF(AND(ISNUMBER(I6),ISNUMBER(J6)),I6*J6,"") -> 16 | L6: =IF(K6="","",IF(K6>=Settings!$C$26,Settings!$C$46,IF(K6>=Settings!$C$27,Settings!$C$47,IF(K6>=Settings!$C$28,Settings!$C$48,Settings!$C$49)))) -> Critical | M6: Open | N6: =IF(B6="","",IF(COUNTA(E6,F6,G6,H6)=4,"Yes","No")) -> Yes | O6: =IF(OR(B6="",M6=Settings!$C$45),"",IF(AND(ISNUMBER(F6),F6<INDEX('Weekly Tracking'!$C$6:$C$29,COUNT('Weekly Tracking'!$E$6:$E$29))),"Yes","No")) -> No | P6: =IF(AND(M6=Settings!$C$44,ISNUMBER(K6)),K6+(100-ROW())/1000,0) -> 16.094
B7: R-02 | C7: Risk | D7: Vendor licenses not delivered | F7: 46295 | G7: Licenses not received by 10/10 | H7: Request temporary licenses | I7: 3 | J7: 3 | K7: =IF(AND(ISNUMBER(I7),ISNUMBER(J7)),I7*J7,"") -> 9 | L7: =IF(K7="","",IF(K7>=Settings!$C$26,Settings!$C$46,IF(K7>=Settings!$C$27,Settings!$C$47,IF(K7>=Settings!$C$28,Settings!$C$48,Settings!$C$49)))) -> High | M7: Open | N7: =IF(B7="","",IF(COUNTA(E7,F7,G7,H7)=4,"Yes","No")) -> No | O7: =IF(OR(B7="",M7=Settings!$C$45),"",IF(AND(ISNUMBER(F7),F7<INDEX('Weekly Tracking'!$C$6:$C$29,COUNT('Weekly Tracking'!$E$6:$E$29))),"Yes","No")) -> Yes | P7: =IF(AND(M7=Settings!$C$44,ISNUMBER(K7)),K7+(100-ROW())/1000,0) -> 9.093
B8: P-01 | C8: Issue | D8: Key user unavailable for testing | E8: PM | F8: 46300 | G8: Materialized | H8: Agree on a substitute with the sponsor | I8: 5 | J8: 3 | K8: =IF(AND(ISNUMBER(I8),ISNUMBER(J8)),I8*J8,"") -> 15 | L8: =IF(K8="","",IF(K8>=Settings!$C$26,Settings!$C$46,IF(K8>=Settings!$C$27,Settings!$C$47,IF(K8>=Settings!$C$28,Settings!$C$48,Settings!$C$49)))) -> Critical | M8: Open | N8: =IF(B8="","",IF(COUNTA(E8,F8,G8,H8)=4,"Yes","No")) -> Yes | O8: =IF(OR(B8="",M8=Settings!$C$45),"",IF(AND(ISNUMBER(F8),F8<INDEX('Weekly Tracking'!$C$6:$C$29,COUNT('Weekly Tracking'!$E$6:$E$29))),"Yes","No")) -> No | P8: =IF(AND(M8=Settings!$C$44,ISNUMBER(K8)),K8+(100-ROW())/1000,0) -> 15.092
B9: R-03 | C9: Risk | D9: Turnover in the infrastructure team | E9: PM | F9: 46309 | G9: Notice of a team member leaving | H9: Document and assign a backup per role | I9: 2 | J9: 3 | K9: =IF(AND(ISNUMBER(I9),ISNUMBER(J9)),I9*J9,"") -> 6 | L9: =IF(K9="","",IF(K9>=Settings!$C$26,Settings!$C$46,IF(K9>=Settings!$C$27,Settings!$C$47,IF(K9>=Settings!$C$28,Settings!$C$48,Settings!$C$49)))) -> Medium | M9: Open | N9: =IF(B9="","",IF(COUNTA(E9,F9,G9,H9)=4,"Yes","No")) -> Yes | O9: =IF(OR(B9="",M9=Settings!$C$45),"",IF(AND(ISNUMBER(F9),F9<INDEX('Weekly Tracking'!$C$6:$C$29,COUNT('Weekly Tracking'!$E$6:$E$29))),"Yes","No")) -> No | P9: =IF(AND(M9=Settings!$C$44,ISNUMBER(K9)),K9+(100-ROW())/1000,0) -> 6.091
B10: R-04 | C10: Risk | D10: Delay in purchasing additional storage | E10: Procurement | F10: 46315 | G10: PO not released by 15/10 | H10: Escalate to procurement leadership | I10: 2 | J10: 4 | K10: =IF(AND(ISNUMBER(I10),ISNUMBER(J10)),I10*J10,"") -> 8 | L10: =IF(K10="","",IF(K10>=Settings!$C$26,Settings!$C$46,IF(K10>=Settings!$C$27,Settings!$C$47,IF(K10>=Settings!$C$28,Settings!$C$48,Settings!$C$49)))) -> High | M10: Open | N10: =IF(B10="","",IF(COUNTA(E10,F10,G10,H10)=4,"Yes","No")) -> Yes | O10: =IF(OR(B10="",M10=Settings!$C$45),"",IF(AND(ISNUMBER(F10),F10<INDEX('Weekly Tracking'!$C$6:$C$29,COUNT('Weekly Tracking'!$E$6:$E$29))),"Yes","No")) -> No | P10: =IF(AND(M10=Settings!$C$44,ISNUMBER(K10)),K10+(100-ROW())/1000,0) -> 8.09
B11: R-05 | C11: Risk | D11: Scope change in reports | E11: PM | F11: 46285 | G11: Formal client request | H11: Change control | I11: 2 | J11: 2 | K11: =IF(AND(ISNUMBER(I11),ISNUMBER(J11)),I11*J11,"") -> 4 | L11: =IF(K11="","",IF(K11>=Settings!$C$26,Settings!$C$46,IF(K11>=Settings!$C$27,Settings!$C$47,IF(K11>=Settings!$C$28,Settings!$C$48,Settings!$C$49)))) -> Medium | M11: Closed | N11: =IF(B11="","",IF(COUNTA(E11,F11,G11,H11)=4,"Yes","No")) -> Yes | O11: =IF(OR(B11="",M11=Settings!$C$45),"",IF(AND(ISNUMBER(F11),F11<INDEX('Weekly Tracking'!$C$6:$C$29,COUNT('Weekly Tracking'!$E$6:$E$29))),"Yes","No")) | P11: =IF(AND(M11=Settings!$C$44,ISNUMBER(K11)),K11+(100-ROW())/1000,0) -> 0
K12: =IF(AND(ISNUMBER(I12),ISNUMBER(J12)),I12*J12,"") | L12: =IF(K12="","",IF(K12>=Settings!$C$26,Settings!$C$46,IF(K12>=Settings!$C$27,Settings!$C$47,IF(K12>=Settings!$C$28,Settings!$C$48,Settings!$C$49)))) | N12: =IF(B12="","",IF(COUNTA(E12,F12,G12,H12)=4,"Yes","No")) | O12: =IF(OR(B12="",M12=Settings!$C$45),"",IF(AND(ISNUMBER(F12),F12<INDEX('Weekly Tracking'!$C$6:$C$29,COUNT('Weekly Tracking'!$E$6:$E$29))),"Yes","No")) | P12: =IF(AND(M12=Settings!$C$44,ISNUMBER(K12)),K12+(100-ROW())/1000,0) -> 0
K13: =IF(AND(ISNUMBER(I13),ISNUMBER(J13)),I13*J13,"") | L13: =IF(K13="","",IF(K13>=Settings!$C$26,Settings!$C$46,IF(K13>=Settings!$C$27,Settings!$C$47,IF(K13>=Settings!$C$28,Settings!$C$48,Settings!$C$49)))) | N13: =IF(B13="","",IF(COUNTA(E13,F13,G13,H13)=4,"Yes","No")) | O13: =IF(OR(B13="",M13=Settings!$C$45),"",IF(AND(ISNUMBER(F13),F13<INDEX('Weekly Tracking'!$C$6:$C$29,COUNT('Weekly Tracking'!$E$6:$E$29))),"Yes","No")) | P13: =IF(AND(M13=Settings!$C$44,ISNUMBER(K13)),K13+(100-ROW())/1000,0) -> 0
K14: =IF(AND(ISNUMBER(I14),ISNUMBER(J14)),I14*J14,"") | L14: =IF(K14="","",IF(K14>=Settings!$C$26,Settings!$C$46,IF(K14>=Settings!$C$27,Settings!$C$47,IF(K14>=Settings!$C$28,Settings!$C$48,Settings!$C$49)))) | N14: =IF(B14="","",IF(COUNTA(E14,F14,G14,H14)=4,"Yes","No")) | O14: =IF(OR(B14="",M14=Settings!$C$45),"",IF(AND(ISNUMBER(F14),F14<INDEX('Weekly Tracking'!$C$6:$C$29,COUNT('Weekly Tracking'!$E$6:$E$29))),"Yes","No")) | P14: =IF(AND(M14=Settings!$C$44,ISNUMBER(K14)),K14+(100-ROW())/1000,0) -> 0
K15: =IF(AND(ISNUMBER(I15),ISNUMBER(J15)),I15*J15,"") | L15: =IF(K15="","",IF(K15>=Settings!$C$26,Settings!$C$46,IF(K15>=Settings!$C$27,Settings!$C$47,IF(K15>=Settings!$C$28,Settings!$C$48,Settings!$C$49)))) | N15: =IF(B15="","",IF(COUNTA(E15,F15,G15,H15)=4,"Yes","No")) | O15: =IF(OR(B15="",M15=Settings!$C$45),"",IF(AND(ISNUMBER(F15),F15<INDEX('Weekly Tracking'!$C$6:$C$29,COUNT('Weekly Tracking'!$E$6:$E$29))),"Yes","No")) | P15: =IF(AND(M15=Settings!$C$44,ISNUMBER(K15)),K15+(100-ROW())/1000,0) -> 0
